Workbook

Sheet Cover
B2: UltraTech Cement Ltd – Integrated Financial Model
B3: Three-statement model, FY22A–FY31E · ₹ Crore unless stated
B4: Prepared by: Ankit Jandial · October 2026
B5: Model status: | C5: =Check!E4 -> MODEL OK
B7: PROJECT QUESTION
B8: Did UltraTech overpay for its South India expansion (India Cements, Kesoram), and what is the stock worth today?
B10: KEY OUTPUTS | C10: FY26A | D10: FY31E
B11: Capacity (mtpa) | C11: =Ops_Forecast!G7 -> 191.4 | D11: =Ops_Forecast!L7 -> 261.1
B12: Consolidated volume (mt) | C12: =Ops_Forecast!G24 -> 154.25 | D12: =Ops_Forecast!L24 -> 226.77592
B13: Revenue (₹ Cr) | C13: =IS!G7 -> 88511.53 | D13: =IS!L7 -> 143672.11
B14: Operating EBITDA (₹ Cr) | C14: =IS!G22 -> 17021.53 | D14: =IS!L22 -> 24210.048
B15: Operating EBITDA margin (%) | C15: =Ops_Forecast!G44 -> 0.19230862 | D15: =Ops_Forecast!L44 -> 0.16850903
B16: Operating EBITDA per tonne (₹/t) | C16: =Ops_Forecast!G39 -> 1103.5028 | D16: =Ops_Forecast!L39 -> 1067.5758
B17: PAT to owners (₹ Cr) | C17: =IS!G33 -> 8166.33 | D17: =IS!L33 -> 13524.909
B18: Cash from operations (₹ Cr) | C18: =CF!G12 -> 15316 | D18: =CF!L12 -> 19725.37
B19: Net debt / EBITDA (x) | C19: =BS!G41 -> 1.0375683 | D19: =BS!L41 -> 0.059034798
B20: Return on equity (%) | C20: =BS!G45 -> 0.11085691 | D20: =BS!L45 -> 0.12235103
B21: Total capex FY27E–FY31E (₹ Cr) | D21: =-SUM(CF!H13:L13) -> 47418.57
B23: ACQUISITION TEST
B24: India Cements EV per mtpa (₹ Cr) | C24: =Acquisition!E23 -> 833.72979
B25: Premium vs building (%) | C25: =Acquisition!E29 -> 0.38954966
B26: Required EBITDA per tonne (₹/t) | C26: =Acquisition!C66 -> 1977.8659
B27: Base-case ROIC (%) | C27: =Acquisition!D82 -> 0.045009907
B28: Price rise needed in South, base case (%) | C28: =Acquisition!D99 -> 0.10249848
B30: SHEET INDEX | C30: What it does
B31: IS | C31: Income statement, history + forecast
B32: BS | C32: Balance sheet; balance check
B33: CF | C33: Cash flow (indirect); cash roll-forward
B34: Ops_Data | C34: Historical operating data from investor decks
B35: Ops_Forecast | C35: Revenue and cost drivers: capacity → volume → ₹/t
B36: Capex_DA | C36: Capex, depreciation and PPE roll-forward
B37: WC | C37: Receivable, inventory and payable days
B38: Debt | C38: Borrowings, repayment and interest
B39: Fin_Inputs | C39: Tax, other income, NCI and dividend assumptions
B40: Acquisition | C40: Price paid for India Cements and Kesoram vs new-build cost; return test.
B41: Check | C41: All model integrity checks
B43: COLOUR CODE
B44: 1000 | C44: Blue | D44: Typed input / historical data
B45: 1000 | C45: Black | D45: Formula (same sheet)
B46: 1000 | C46: Green | D46: Link from another sheet

Sheet IS
B2: INCOME STATEMENT
B3: Model status: | C3: =Check!E4 -> MODEL OK
C5: FY22A | D5: FY23A | E5: FY24A | F5: FY25A | G5: FY26A | H5: FY27E | I5: FY28E | J5: FY29E | K5: FY30E | L5: FY31E | M5: Source
B6: REVENUE
B7: Revenue from operations | C7: 52599 | D7: 63240 | E7: 70909 | F7: 75955 | G7: 88511.53 | H7: =Ops_Forecast!H28 -> 99039.238 | I7: =Ops_Forecast!I28 -> 109879.89 | J7: =Ops_Forecast!J28 -> 120857.38 | K7: =Ops_Forecast!K28 -> 131770.73 | L7: =Ops_Forecast!L28 -> 143672.11 | M7: Hist: AR consol. P&L (Note 25). Fcst: Ops_Forecast revenue (volume x revenue/t)
B8: Other income | C8: 508 | D8: 503 | E8: 617 | F8: 744 | G8: 578 | H8: =Fin_Inputs!H8*(BS!G14+BS!G15+BS!G10) -> 609.3 | I8: =Fin_Inputs!H8*(BS!H14+BS!H15+BS!H10) -> 649.77179 | J8: =Fin_Inputs!I8*(BS!I14+BS!I15+BS!I10) -> 658.47535 | K8: =Fin_Inputs!J8*(BS!J14+BS!J15+BS!J10) -> 658.0771 | L8: =Fin_Inputs!K8*(BS!K14+BS!K15+BS!K10) -> 737.68377 | M8: Hist: AR (Note 26), interest & treasury income. Fcst: yield (Fin_Inputs) x last year's cash & bank + current inv. + non-current inv.
B9: Total income | C9: =SUM(C7:C8) -> 53107 | D9: =SUM(D7:D8) -> 63743 | E9: =SUM(E7:E8) -> 71526 | F9: =SUM(F7:F8) -> 76699 | G9: =SUM(G7:G8) -> 89089.53 | H9: =SUM(H7:H8) -> 99648.538 | I9: =SUM(I7:I8) -> 110529.66 | J9: =SUM(J7:J8) -> 121515.86 | ... L9: =SUM(L7:L8) -> 144409.8 | M9: Revenue + other income
B11: OPERATING EXPENSES
B12: Cost of materials consumed | C12: 7096 | D12: 8933 | E12: 10252 | F12: 11822 | G12: 14568 | H12: =Ops_Forecast!H33*Ops_Forecast!H24/10 -> 19798.027 | I12: =Ops_Forecast!I33*Ops_Forecast!I24/10 -> 22611.114 | J12: =Ops_Forecast!J33*Ops_Forecast!J24/10 -> 25601.539 | K12: =Ops_Forecast!K33*Ops_Forecast!K24/10 -> 28734.322 | L12: =Ops_Forecast!L33*Ops_Forecast!L24/10 -> 32251.031 | M12: Hist: AR (Note 27). Fcst: raw materials Rs/t x volume / 10 (Ops_Forecast). Includes purchases and inventory change
B13: Purchases of stock-in-trade | C13: 1252 | D13: 1300 | E13: 1734 | F13: 1870 | G13: 2517 | H13: 0 | I13: 0 | J13: 0 | K13: 0 | L13: 0 | M13: Hist: AR (Note 28). Fcst: 0, included in cost of materials consumed
B14: Changes in inventories | C14: -383 | D14: -518 | E14: -83 | F14: 12 | G14: 103 | H14: 0 | I14: 0 | J14: 0 | K14: 0 | L14: 0 | M14: Hist: AR (Note 29), sign as reported. Fcst: 0, included in cost of materials consumed
B15: Employee benefits expense | C15: 2535 | D15: 2739 | E15: 3038 | F15: 3605 | G15: 4162 | H15: =Ops_Forecast!H32 -> 4494.96 | I15: =Ops_Forecast!I32 -> 4854.5568 | J15: =Ops_Forecast!J32 -> 5242.9213 | K15: =Ops_Forecast!K32 -> 5662.3551 | L15: =Ops_Forecast!L32 -> 6115.3435 | M15: Hist: AR (Note 30). Fcst: Ops_Forecast employee cost (fixed, +8%/yr)
B16: Power and fuel | C16: 12137 | D16: 18491 | E16: 18283 | F16: 18419 | G16: 19597 | H16: =Ops_Forecast!H34*Ops_Forecast!H24/10 -> 22357.858 | I16: =Ops_Forecast!I34*Ops_Forecast!I24/10 -> 24318.734 | J16: =Ops_Forecast!J34*Ops_Forecast!J24/10 -> 26748.284 | K16: =Ops_Forecast!K34*Ops_Forecast!K24/10 -> 29163.638 | L16: =Ops_Forecast!L34*Ops_Forecast!L24/10 -> 31797.664 | M16: Hist: AR P&L. Fcst: power & fuel Rs/t x volume / 10 (Ops_Forecast)
B17: Freight and forwarding | C17: 11712 | D17: 14009 | E17: 15881 | F17: 17460 | G17: 19169 | H17: =Ops_Forecast!H35*Ops_Forecast!H24/10 -> 21448.993 | I17: =Ops_Forecast!I35*Ops_Forecast!I24/10 -> 23563.458 | J17: =Ops_Forecast!J35*Ops_Forecast!J24/10 -> 25663.46 | K17: =Ops_Forecast!K35*Ops_Forecast!K24/10 -> 27706.532 | L17: =Ops_Forecast!L35*Ops_Forecast!L24/10 -> 29912.788 | M17: Hist: AR (Note 33). Fcst: freight Rs/t x volume / 10 (Ops_Forecast)
B18: Other expenses | C18: 6735 | D18: 7666 | E18: 8835 | F18: 10210 | G18: 11374 | H18: =Ops_Forecast!H37*Ops_Forecast!H24/10 -> 12851.615 | I18: =Ops_Forecast!I37*Ops_Forecast!I24/10 -> 14398.117 | J18: =Ops_Forecast!J37*Ops_Forecast!J24/10 -> 15991.814 | K18: =Ops_Forecast!K37*Ops_Forecast!K24/10 -> 17606.804 | L18: =Ops_Forecast!L37*Ops_Forecast!L24/10 -> 19385.237 | M18: Hist: AR (Note 34). Fcst: other expenses Rs/t x volume / 10 (Ops_Forecast)
B19: Total operating expenses | C19: =SUM(C12:C18) -> 41084 | D19: =SUM(D12:D18) -> 52620 | E19: =SUM(E12:E18) -> 57940 | F19: =SUM(F12:F18) -> 63398 | G19: =SUM(G12:G18) -> 71490 | H19: =SUM(H12:H18) -> 80951.453 | I19: =SUM(I12:I18) -> 89745.98 | J19: =SUM(J12:J18) -> 99248.018 | ... L19: =SUM(L12:L18) -> 119462.06 | M19: Sum of operating expenses. Fcst ties to Ops_Forecast total operating costs (check)
B21: PROFITABILITY
B22: Operating EBITDA | C22: =C7-C19 -> 11515 | D22: =D7-D19 -> 10620 | E22: =E7-E19 -> 12969 | F22: =F7-F19 -> 12557 | G22: =G7-G19 -> 17021.53 | H22: =H7-H19 -> 18087.784 | I22: =I7-I19 -> 20133.91 | J22: =J7-J19 -> 21609.366 | ... L22: =L7-L19 -> 24210.048 | M22: total operating expenses. Excludes other income
B23: EBITDA (incl. other income) | C23: =C22+C8 -> 12023 | D23: =D22+D8 -> 11123 | E23: =E22+E8 -> 13586 | F23: =F22+F8 -> 13301 | G23: =G22+G8 -> 17599.53 | H23: =H22+H8 -> 18697.084 | I23: =I22+I8 -> 20783.682 | J23: =J22+J8 -> 22267.842 | ... L23: =L22+L8 -> 24947.732 | M23: Operating EBITDA + other income. Ties to company-reported EBITDA (hist)
B24: Depreciation and amortisation | C24: 2715 | D24: 2888 | E24: 3145 | F24: 4015 | G24: 4644 | H24: =Capex_DA!H22 -> 4996.522 | I24: =Capex_DA!I22 -> 5261.7063 | J24: =Capex_DA!J22 -> 5512.8359 | K24: =Capex_DA!K22 -> 5710.4778 | L24: =Capex_DA!L22 -> 5869.4146 | M24: Hist: AR (Note 32). Fcst: Capex_DA (5.3% x opening PPE + 50% capex)
B25: EBIT | C25: =C23-C24 -> 9308 | D25: =D23-D24 -> 8235 | E25: =E23-E24 -> 10441 | F25: =F23-F24 -> 9286 | G25: =G23-G24 -> 12955.53 | H25: =H23-H24 -> 13700.562 | I25: =I23-I24 -> 15521.975 | J25: =J23-J24 -> 16755.006 | ... L25: =L23-L24 -> 19078.317 | M25: D&A
B26: Finance costs | C26: 945 | D26: 823 | E26: 968 | F26: 1651 | G26: 1872 | H26: =Debt!H18 -> 1822.48 | I26: =Debt!I18 -> 1742.48 | J26: =Debt!J18 -> 1542.48 | K26: =Debt!K18 -> 1262.48 | L26: =Debt!L18 -> 942.48 | M26: Hist: AR (Note 31). Fcst: Debt sheet (8.0% x average gross debt)
B27: Exceptional items | C27: 0 | D27: 0 | E27: -72 | F27: -97 | G27: -139 | H27: =Fin_Inputs!H9 -> 0 | I27: =Fin_Inputs!I9 -> 0 | J27: =Fin_Inputs!J9 -> 0 | K27: =Fin_Inputs!K9 -> 0 | L27: =Fin_Inputs!L9 -> 0 | M27: Hist: AR (FY24-26 stamp duty, impairment, labour codes). Fcst: 0, one-offs not forecast
B28: Share of profit of associates/JVs | C28: 2 | D28: 4.03 | E28: 22 | F28: -11 | G28: -16 | H28: =Fin_Inputs!H10 -> 0 | I28: =Fin_Inputs!I10 -> 0 | J28: =Fin_Inputs!J10 -> 0 | K28: =Fin_Inputs!K10 -> 0 | L28: =Fin_Inputs!L10 -> 0 | M28: Hist: AR. Fcst: 0
B29: Profit before tax | C29: =C25-C26+C27+C28 -> 8365 | D29: =D25-D26+D27+D28 -> 7416.03 | E29: =E25-E26+E27+E28 -> 9423 | F29: =F25-F26+F27+F28 -> 7527 | G29: =G25-G26+G27+G28 -> 10928.53 | H29: =H25-H26+H27+H28 -> 11878.082 | I29: =I25-I26+I27+I28 -> 13779.495 | J29: =J25-J26+J27+J28 -> 15212.526 | ... L29: =L25-L26+L27+L28 -> 18135.837 | M29: finance costs + exceptional items + associates
B30: Tax expense | C30: 1190 | D30: 2343 | E30: 2418.55 | F30: 1487.75 | G30: 2739.49 | H30: =H29*Fin_Inputs!H7 -> 2993.2768 | I30: =I29*Fin_Inputs!I7 -> 3472.4328 | J30: =J29*Fin_Inputs!J7 -> 3833.5565 | K30: =K29*Fin_Inputs!K7 -> 4178.7139 | L30: =L29*Fin_Inputs!L7 -> 4570.2309 | M30: Hist: AR. FY22 incl. Rs305 Cr reversal. Fcst: 25.2% x PBT (new-regime statutory rate)
B31: Profit after tax | C31: =C29-C30 -> 7175 | D31: =D29-D30 -> 5073.03 | E31: =E29-E30 -> 7004.45 | F31: =F29-F30 -> 6039.25 | G31: =G29-G30 -> 8189.04 | H31: =H29-H30 -> 8884.8056 | I31: =I29-I30 -> 10307.063 | J31: =J29-J30 -> 11378.969 | ... L31: =L29-L30 -> 13565.606 | M31: tax. FY22 = continuing operations only
B32: Attributable to non-controlling interests | C32: -10.05 | D32: 9.44 | E32: -1.04 | F32: 0.53 | G32: 22.71 | H32: =H31*Fin_Inputs!H11 -> 26.654417 | I32: =I31*Fin_Inputs!I11 -> 30.921188 | J32: =J31*Fin_Inputs!J11 -> 34.136908 | K32: =K31*Fin_Inputs!K11 -> 37.210453 | L32: =L31*Fin_Inputs!L11 -> 40.696818 | M32: Hist: AR. Fcst: 0.3% x PAT (FY26 actual; India Cements minority)
B33: PAT attributable to owners | C33: =C31-C32 -> 7185.05 | D33: =D31-D32 -> 5063.59 | E33: =E31-E32 -> 7005.49 | F33: =F31-F32 -> 6038.72 | G33: =G31-G32 -> 8166.33 | H33: =H31-H32 -> 8858.1512 | I33: =I31-I32 -> 10276.141 | J33: =J31-J32 -> 11344.832 | ... L33: =L31-L32 -> 13524.909 | M33: NCI. Ties to 'Profit attributable to Owners of the Parent'
B35: RATIOS
B36: Revenue growth % | D36: =IF(C7=0,0,(D7/C7)-1) -> 0.20230423 | E36: =IF(D7=0,0,E7/D7-1) -> 0.12126818 | F36: =IF(E7=0,0,F7/E7-1) -> 0.07116163 | G36: =IF(F7=0,0,G7/F7-1) -> 0.16531538 | H36: =IF(G7=0,0,H7/G7-1) -> 0.11894165 | I36: =IF(H7=0,0,I7/H7-1) -> 0.10945815 | J36: =IF(I7=0,0,J7/I7-1) -> 0.099904497 | K36: =IF(J7=0,0,K7/J7-1) -> 0.090299369 | L36: =IF(K7=0,0,L7/K7-1) -> 0.090318851 | M36: 1. FY25 inflated by Kesoram restatement
B37: Operating EBITDA margin % | C37: =IF(C7=0,0,C22/C7) -> 0.21892051 | D37: =IF(D7=0,0,D22/D7) -> 0.16793169 | E37: =IF(E7=0,0,E22/E7) -> 0.18289639 | F37: =IF(F7=0,0,F22/F7) -> 0.16532157 | G37: =IF(G7=0,0,G22/G7) -> 0.19230862 | H37: =IF(H7=0,0,H22/H7) -> 0.18263251 | I37: =IF(I7=0,0,I22/I7) -> 0.18323562 | J37: =IF(J7=0,0,J22/J7) -> 0.17880055 | ... L37: =IF(L7=0,0,L22/L7) -> 0.16850903 | M37: Operating EBITDA / revenue. Falls 19.2% to 16.9% (price +2% vs costs ~2.6%)
B38: PAT margin % | C38: =IF(C7=0,0,C31/C7) -> 0.13640944 | D38: =IF(D7=0,0,D31/D7) -> 0.080218691 | E38: =IF(E7=0,0,E31/E7) -> 0.098780832 | F38: =IF(F7=0,0,F31/F7) -> 0.079510895 | G38: =IF(G7=0,0,G31/G7) -> 0.092519472 | H38: =IF(H7=0,0,H31/H7) -> 0.089709956 | I38: =IF(I7=0,0,I31/I7) -> 0.093802993 | J38: =IF(J7=0,0,J31/J7) -> 0.09415204 | ... L38: =IF(L7=0,0,L31/L7) -> 0.094420594 | M38: PAT / revenue. Rises as finance costs fall
B39: Effective tax rate % | C39: =IF(C29=0,0,C30/C29) -> 0.14225941 | D39: =IF(D29=0,0,D30/D29) -> 0.31593723 | E39: =IF(E29=0,0,E30/E29) -> 0.25666454 | F39: =IF(F29=0,0,F30/F29) -> 0.19765511 | G39: =IF(G29=0,0,G30/G29) -> 0.25067324 | H39: =IF(H29=0,0,H30/H29) -> 0.252 | I39: =IF(I29=0,0,I30/I29) -> 0.252 | J39: =IF(J29=0,0,J30/J29) -> 0.252 | ... L39: =IF(L29=0,0,L30/L29) -> 0.252 | M39: Tax / PBT. Fcst = 25.2% input

Sheet BS
B2: BALANCE SHEET
B3: Model status: | C3: =Check!E4 -> MODEL OK
C5: FY22A | D5: FY23A | E5: FY24A | F5: FY25A | G5: FY26A | H5: FY27E | I5: FY28E | J5: FY29E | K5: FY30E | L5: FY31E | M5: Source
B6: ASSETS
B7: PPE (incl. CWIP, ROU) | C7: 48548 | D7: 51706 | E7: 57825 | F7: 83039 | G7: 89274 | H7: =Capex_DA!H23 -> 94277.478 | I7: =Capex_DA!I23 -> 99015.772 | J7: =Capex_DA!J23 -> 103502.94 | K7: =Capex_DA!K23 -> 106276.31 | L7: =Capex_DA!L23 -> 109341.61 | M7: BS: Property, Plant & Equipment + Capital Work-in-Progress (Note 2) + Right of Use Assets (Note 3A)
B8: Goodwill | C8: 6250 | D8: 6329 | E8: 6345 | F8: 7682 | G8: 7909 | H8: =G8 -> 7909 | I8: =H8 -> 7909 | J8: =I8 -> 7909 | K8: =J8 -> 7909 | L8: =K8 -> 7909 | M8: BS: Goodwill (Note 2)
B9: Other intangibles | C9: 5474 | D9: 5585 | E9: 5518 | F9: 10077 | G9: 10353 | H9: =G9 -> 10353 | I9: =H9 -> 10353 | J9: =I9 -> 10353 | K9: =J9 -> 10353 | L9: =K9 -> 10353 | M9: BS: Other Intangible Assets + Intangible Assets under Development (Note 2)
B10: Non-current investments | C10: 1372 | D10: 1460 | E10: 2764 | F10: 2297 | G10: 3004 | H10: =G10 -> 3004 | I10: =H10 -> 3004 | J10: =I10 -> 3004 | K10: =J10 -> 3004 | L10: =K10 -> 3004 | M10: BS: Investments Accounted using Equity Method (Note 4) + Non-current Investments (Note 5)
B11: Other non-current assets | C11: 4694 | D11: 5564 | E11: 5191 | F11: 6864 | G11: 5589 | H11: =G11 -> 5589 | I11: =H11 -> 5589 | J11: =I11 -> 5589 | K11: =J11 -> 5589 | L11: =K11 -> 5589 | M11: BS: Non-current Loans (Note 6) + Other Financial Assets (Note 7) + Deferred Tax Assets (Note 8) + Income Tax Assets + Other Non-Current Assets (Note 9)
B12: Inventories | C12: 5596 | D12: 6612 | E12: 8330 | F12: 9563 | G12: 9694 | H12: =WC!H14 -> 10853.615 | I12: =WC!I14 -> 12041.632 | J12: =WC!J14 -> 13244.645 | K12: =WC!K14 -> 14440.628 | L12: =WC!L14 -> 15744.889 | M12: BS: Inventories (Note 10)
B13: Trade receivables | C13: 3072 | D13: 3867 | E13: 4278 | F13: 5890 | G13: 6029 | H13: =WC!H13 -> 6512.1691 | I13: =WC!I13 -> 6923.9382 | J13: =WC!J13 -> 7284.5547 | K13: =WC!K13 -> 7942.3454 | L13: =WC!L13 -> 8659.6889 | M13: BS: Trade Receivables (Note 12)
B14: Cash & bank balances | C14: 359 | D14: 1149.55 | E14: 783 | F14: 1673 | G14: 1384 | H14: =CF!H22 -> 1923.6238 | I14: =CF!I22 -> 2039.6714 | J14: =CF!J22 -> 2034.3613 | K14: =CF!K22 -> 3095.7836 | L14: =CF!L22 -> 4615.7647 | M14: BS: Cash and Cash Equivalents (Note 13) + Other Bank Balances (Note 14)
B15: Current investments | C15: 4963.55 | D15: 5836.75 | E15: 5485.26 | F15: 2859 | G15: 3736 | H15: =G15 -> 3736 | I15: =H15 -> 3736 | J15: =I15 -> 3736 | K15: =J15 -> 3736 | L15: =K15 -> 3736 | M15: BS: Current Investments (Note 11)
B16: Other current assets | C16: 3500 | D16: 3277.65 | E16: 4282.26 | F16: 3752 | G16: 4404 | H16: =G16 -> 4404 | I16: =H16 -> 4404 | J16: =I16 -> 4404 | K16: =J16 -> 4404 | L16: =K16 -> 4404 | M16: BS: Current Loans (Note 6) + Other Financial Assets (Note 7) + Income Tax Assets + Other Current Assets (Note 15) + Assets Held for Sale
B17: Total assets | C17: =SUM(C7:C16) -> 83828.55 | D17: =SUM(D7:D16) -> 91386.95 | E17: =SUM(E7:E16) -> 100801.52 | F17: =SUM(F7:F16) -> 133696 | G17: =SUM(G7:G16) -> 141376 | H17: =SUM(H7:H16) -> 148561.89 | I17: =SUM(I7:I16) -> 155016.01 | J17: =SUM(J7:J16) -> 161061.5 | ... L17: =SUM(L7:L16) -> 173356.96 | M17: Formula: Sum of assets. Ties to 'TOTAL ASSETS'
B19: EQUITY
B20: Share capital | C20: 289 | D20: 289 | E20: 289 | F20: 295 | G20: 295 | H20: =G20 -> 295 | I20: =H20 -> 295 | J20: =I20 -> 295 | K20: =J20 -> 295 | L20: =K20 -> 295 | M20: BS: Equity Share Capital (Note 16a)
B21: Other equity | C21: 50147 | D21: 54036 | E21: 59938.51 | F21: 70412 | G21: 76329 | H21: =G21+IS!H33-Fin_Inputs!H12 -> 82328.936 | I21: =H21+IS!I33-Fin_Inputs!I12 -> 89504.724 | J21: =I21+IS!J33-Fin_Inputs!J12 -> 97252.907 | K21: =J21+IS!K33-Fin_Inputs!K12 -> 105648.49 | L21: =K21+IS!L33-Fin_Inputs!L12 -> 114845.2 | M21: BS: Other Equity (Note 16b). FY24/FY25 include share application money pending allotment
B22: Non-controlling interest | C22: -3.49 | D22: 56 | E22: 55.8 | F22: 3187 | G22: 4089 | H22: =G22+IS!H32 -> 4115.6544 | I22: =H22+IS!I32 -> 4146.5756 | J22: =I22+IS!J32 -> 4180.7125 | K22: =J22+IS!K32 -> 4217.923 | L22: =K22+IS!L32 -> 4258.6198 | M22: BS: Non-Controlling Interest. Jumps in FY25 (India Cements minority shareholders)
B23: Total Equity | C23: =SUM(C20:C22) -> 50432.51 | D23: =SUM(D20:D22) -> 54381 | E23: =SUM(E20:E22) -> 60283.31 | F23: =SUM(F20:F22) -> 73894 | G23: =SUM(G20:G22) -> 80713 | H23: =SUM(H20:H22) -> 86739.59 | I23: =SUM(I20:I22) -> 93946.3 | J23: =SUM(J20:J22) -> 101728.62 | ... L23: =SUM(L20:L22) -> 119398.82 | M23: Formula: Share capital + Other equity + NCI
B25: LIABILITIES
B26: Long-term borrowing | C26: 5302.51 | D26: 5356.45 | E26: 5307.75 | F26: 15781 | G26: 15019 | H26: =Debt!H12 -> 15019 | I26: =Debt!I12 -> 13019 | J26: =Debt!J12 -> 10019 | K26: =Debt!K12 -> 6019 | L26: =Debt!L12 -> 2019 | M26: BS: Non-current Borrowings (Note 17)
B27: Short-term borrowing | C27: 4900 | D27: 4544.45 | E27: 4990.55 | F27: 7250 | G27: 7762 | H27: =Debt!H13 -> 7762 | I27: =Debt!I13 -> 7762 | J27: =Debt!J13 -> 7762 | K27: =Debt!K13 -> 7762 | L27: =Debt!L13 -> 7762 | M27: BS: Current Borrowings (Note 22). Includes current maturities of long-term debt
B28: Lease liabilities | C28: 1096.4 | D28: 1157 | E28: 1105 | F28: 1071 | G28: 974 | H28: =G28 -> 974 | I28: =H28 -> 974 | J28: =I28 -> 974 | K28: =J28 -> 974 | L28: =K28 -> 974 | M28: BS: Lease Liabilities, non-current + current (Note 3B)
B29: Trade payables | C29: 5863 | D29: 7208.5 | E29: 8477.75 | F29: 9327 | G29: 10237 | H29: =WC!H15 -> 11396.296 | I29: =WC!I15 -> 12643.713 | J29: =WC!J15 -> 13906.877 | K29: =WC!K15 -> 15162.659 | L29: =WC!L15 -> 16532.133 | M29: BS: Trade Payables, MSME + others (Note 23)
B30: Deferred tax liabilities | C30: 6033 | D30: 6260 | E30: 6447.75 | F30: 9579 | G30: 9890 | H30: =G30 -> 9890 | I30: =H30 -> 9890 | J30: =I30 -> 9890 | K30: =J30 -> 9890 | L30: =K30 -> 9890 | M30: BS: Deferred Tax Liabilities (Net) (Note 20)
B31: Other non-current liabilities | C31: 926 | D31: 948 | E31: 914.75 | F31: 1210 | G31: 1171 | H31: =G31 -> 1171 | I31: =H31 -> 1171 | J31: =I31 -> 1171 | K31: =J31 -> 1171 | L31: =K31 -> 1171 | M31: BS: Non-current Other Financial Liabilities (Note 18) + Provisions (Note 19) + Other Non-Current Liabilities (Note 21)
B32: Other current liabilities | C32: 9274.75 | D32: 11532 | E32: 13274.75 | F32: 15584 | G32: 15610 | H32: =G32 -> 15610 | I32: =H32 -> 15610 | J32: =I32 -> 15610 | K32: =J32 -> 15610 | L32: =K32 -> 15610 | M32: BS: Current Other Financial Liabilities (Note 18) + Other Current Liabilities (Note 24) + Provisions (Note 19) + Current Tax Liabilities
B33: Total liabilities | C33: =SUM(C26:C32) -> 33395.66 | D33: =SUM(D26:D32) -> 37006.4 | E33: =SUM(E26:E32) -> 40518.3 | F33: =SUM(F26:F32) -> 59802 | G33: =SUM(G26:G32) -> 60663 | H33: =SUM(H26:H32) -> 61822.296 | I33: =SUM(I26:I32) -> 61069.713 | J33: =SUM(J26:J32) -> 59332.877 | ... L33: =SUM(L26:L32) -> 53958.133 | M33: Formula: Sum of liabilities
B35: Total equity and liabilities | C35: =C33+C23 -> 83828.17 | D35: =D33+D23 -> 91387.4 | E35: =E33+E23 -> 100801.61 | F35: =F33+F23 -> 133696 | G35: =G33+G23 -> 141376 | H35: =H33+H23 -> 148561.89 | I35: =I33+I23 -> 155016.01 | J35: =J33+J23 -> 161061.5 | ... L35: =L33+L23 -> 173356.96 | M35: Formula: Total equity + Total liabilities. Ties to 'TOTAL EQUITY AND LIABILITIES'
B36: Balance check | C36: =ROUND(C17-C35,0) -> 0 | D36: =ROUND(D17-D35,0) -> 0 | E36: =ROUND(E17-E35,0) -> 0 | F36: =ROUND(F17-F35,0) -> 0 | G36: =ROUND(G17-G35,0) -> 0 | H36: =ROUND(H17-H35,0) -> 0 | I36: =ROUND(I17-I35,0) -> 0 | J36: =ROUND(J17-J35,0) -> 0 | ... L36: =ROUND(L17-L35,0) -> 0 | M36: Total equity and liabilities, 0). Must be 0
B38: RATIOS
B39: Gross debt | C39: =C26+C27 -> 10202.51 | D39: =D26+D27 -> 9900.9 | E39: =E26+E27 -> 10298.3 | F39: =F26+F27 -> 23031 | G39: =G26+G27 -> 22781 | H39: =H26+H27 -> 22781 | I39: =I26+I27 -> 20781 | J39: =J26+J27 -> 17781 | ... L39: =L26+L27 -> 9781 | M39: Formula: Long-term + Short-term borrowings. Excludes lease liabilities
B40: Net debt | C40: =C39-C14-C15 -> 4879.96 | D40: =D39-D14-D15 -> 2914.6 | E40: =E39-E14-E15 -> 4030.04 | F40: =F39-F14-F15 -> 18499 | G40: =G39-G14-G15 -> 17661 | H40: =H39-H14-H15 -> 17121.376 | I40: =I39-I14-I15 -> 15005.329 | J40: =J39-J14-J15 -> 12010.639 | ... L40: =L39-L14-L15 -> 1429.2353 | M40: Current investments. Company reports lower (counts more liquid investments as cash)
B41: Net debt / EBITDA | C41: =C40/IS!C22 -> 0.42379158 | D41: =D40/IS!D22 -> 0.27444444 | E41: =E40/IS!E22 -> 0.31074408 | F41: =F40/IS!F22 -> 1.4732022 | G41: =G40/IS!G22 -> 1.0375683 | H41: =H40/IS!H22 -> 0.94657122 | I41: =I40/IS!I22 -> 0.74527644 | J41: =J40/IS!J22 -> 0.55580707 | ... L41: =L40/IS!L22 -> 0.059034798 | M41: Formula: Net debt / EBITDA incl. other income (Hist_IS). Company reported 1.33x FY25, 0.94x FY26
B42: Receivable days | C42: =(C13/IS!C7)*365 -> 21.317516 | D42: =(D13/IS!D7)*365 -> 22.319023 | E42: =(E13/IS!E7)*365 -> 22.020759 | F42: =(F13/IS!F7)*365 -> 28.304259 | G42: =(G13/IS!G7)*365 -> 24.862128 | H42: =(H13/IS!H7)*365 -> 24 | I42: =(I13/IS!I7)*365 -> 23 | J42: =(J13/IS!J7)*365 -> 22 | ... L42: =(L13/IS!L7)*365 -> 22 | M42: Formula: Trade receivables / Revenue from operations x 365
B43: Inventory days | C43: =(C12/IS!C7)*365 -> 38.832297 | D43: =(D12/IS!D7)*365 -> 38.162239 | E43: =(E12/IS!E7)*365 -> 42.878196 | F43: =(F12/IS!F7)*365 -> 45.954776 | G43: =(G12/IS!G7)*365 -> 39.975696 | H43: =(H12/IS!H7)*365 -> 40 | I43: =(I12/IS!I7)*365 -> 40 | J43: =(J12/IS!J7)*365 -> 40 | ... L43: =(L12/IS!L7)*365 -> 40 | M43: Formula: Inventories / Revenue from operations x 365. Revenue basis used for forecast consistency
B44: Payable days | C44: =(C29/IS!C7)*365 -> 40.685089 | D44: =(D29/IS!D7)*365 -> 41.605036 | E44: =(E29/IS!E7)*365 -> 43.638731 | F44: =(F29/IS!F7)*365 -> 44.820683 | G44: =(G29/IS!G7)*365 -> 42.214896 | H44: =(H29/IS!H7)*365 -> 42 | I44: =(I29/IS!I7)*365 -> 42 | J44: =(J29/IS!J7)*365 -> 42 | ... L44: =(L29/IS!L7)*365 -> 42 | M44: Formula: Trade payables / Revenue from operations x 365. Revenue basis used for forecast consistency
B45: Return on equity | D45: =(IS!D33)/(SUM(C20:D21)/2) -> 0.096669371 | E45: =(IS!E33)/(SUM(D20:E21)/2) -> 0.12231055 | F45: =(IS!F33)/(SUM(E20:F21)/2) -> 0.092240312 | G45: =(IS!G33)/(SUM(F20:G21)/2) -> 0.11085691 | H45: =(IS!H33)/(SUM(G20:H21)/2) -> 0.11124981 | I45: =(IS!I33)/(SUM(H20:I21)/2) -> 0.11919642 | J45: =(IS!J33)/(SUM(I20:J21)/2) -> 0.12110996 | K45: =(IS!K33)/(SUM(J20:K21)/2) -> 0.121541 | L45: =(IS!L33)/(SUM(K20:L21)/2) -> 0.12235103 | M45: Formula: PAT to owners / Average (Share capital + Other equity). FY22 blank (no FY21)

Sheet CF
B2: CASH FLOW STATEMENT
B3: Model status: | C3: =Check!E4 -> MODEL OK
C5: FY22A | D5: FY23A | E5: FY24A | F5: FY25A | G5: FY26A | H5: FY27E | I5: FY28E | J5: FY29E | K5: FY30E | L5: FY31E | M5: Source
B6: CASH FLOW
B7: Profit after tax | C7: =IS!C31 -> 7175 | D7: =IS!D31 -> 5073.03 | E7: =IS!E31 -> 7004.45 | F7: =IS!F31 -> 6039.25 | G7: =IS!G31 -> 8189.04 | H7: =IS!H31 -> 8884.8056 | I7: =IS!I31 -> 10307.063 | J7: =IS!J31 -> 11378.969 | ... L7: =IS!L31 -> 13565.606 | M7: Profit after tax — Link: IS PAT (total, incl. NCI share)
B8: Depreciation & amortisation | C8: =IS!C24 -> 2715 | D8: =IS!D24 -> 2888 | E8: =IS!E24 -> 3145 | F8: =IS!F24 -> 4015 | G8: =IS!G24 -> 4644 | H8: =IS!H24 -> 4996.522 | I8: =IS!I24 -> 5261.7063 | J8: =IS!J24 -> 5512.8359 | ... L8: =IS!L24 -> 5869.4146 | M8: Depreciation & amortisation — Link: IS; non-cash, added back
B9: Finance costs | C9: =IS!C26 -> 945 | D9: =IS!D26 -> 823 | E9: =IS!E26 -> 968 | F9: =IS!F26 -> 1651 | G9: =IS!G26 -> 1872 | H9: =IS!H26 -> 1822.48 | I9: =IS!I26 -> 1742.48 | J9: =IS!J26 -> 1542.48 | ... L9: =IS!L26 -> 942.48 | M9: Finance costs — Link: IS; added back here because interest paid is shown separately below
B10: (Increase)/decrease in working capital | D10: =WC!D21 -> -465.5 | E10: =WC!E21 -> -859.75 | F10: =WC!F21 -> -1995.75 | G10: =WC!G21 -> 640 | H10: =WC!H21 -> -483.4883 | I10: =WC!I21 -> -352.36836 | J10: =WC!J21 -> -300.46579 | K10: =WC!K21 -> -597.99154 | L10: =WC!L21 -> -652.13046 | M10: (Increase)/decrease in working capital — Link: WC sheet; FY22 not computable (no FY21 balance sheet), included in other items
B11: Other operating items | C11: =C12-SUM(C7:C10) -> -1552 | D11: =D12-SUM(D7:D10) -> 750.22 | E11: =E12-SUM(E7:E10) -> 639.85 | F11: =F12-SUM(F7:F10) -> 963.5 | G11: =G12-SUM(G7:G10) -> -29.04 | H11: 0 | I11: 0 | J11: 0 | K11: 0 | L11: 0 | M11: Other operating items — Hist: plug = reported CFO − rows above (tax paid vs expense, other non-cash items, other WC items); Forecast: assumed 0
B12: Cash from operations (CFO) | C12: 9283 | D12: 9068.75 | E12: 10897.55 | F12: 10673 | G12: 15316 | H12: =SUM(H7:H11) -> 15220.319 | I12: =SUM(I7:I11) -> 16958.88 | J12: =SUM(J7:J11) -> 18133.819 | K12: =SUM(K7:K11) -> 18778.451 | L12: =SUM(L7:L11) -> 19725.37 | M12: Cash from operations (CFO) — Hist: consolidated cash flow statement, AR FY22 p.286, AR FY24 p.374 (incl. FY23), AR FY26 p.466 (incl. FY25); Forecast: sum of rows above
B13: Capex | C13: -5613 | D13: -6200.49 | E13: -9006 | F13: -9129 | G13: -9678 | H13: =-Capex_DA!H19 -> -10000 | I13: =-Capex_DA!I19 -> -10000 | J13: =-Capex_DA!J19 -> -10000 | K13: =-Capex_DA!K19 -> -8483.8569 | L13: =-Capex_DA!L19 -> -8934.7132 | M13: Capex — Hist: CF statement, purchase of PPE & intangibles (investing activities); Forecast: Capex_DA sheet
B14: Free cash flow (FCF) | C14: =C12+C13 -> 3670 | D14: =D12+D13 -> 2868.26 | E14: =E12+E13 -> 1891.55 | F14: =F12+F13 -> 1544 | G14: =G12+G13 -> 5638 | H14: =H12+H13 -> 5220.3193 | I14: =I12+I13 -> 6958.8805 | J14: =J12+J13 -> 8133.8194 | ... L14: =L12+L13 -> 10790.657 | M14: Free cash flow (FCF) — Calc: CFO − capex
B15: Interest paid | C15: -961 | D15: -702 | E15: -853.45 | F15: -1479 | G15: -1869 | H15: =-IS!H26 -> -1822.48 | I15: =-IS!I26 -> -1742.48 | J15: =-IS!J26 -> -1542.48 | K15: =-IS!K26 -> -1262.48 | L15: =-IS!L26 -> -942.48 | M15: Interest paid — Hist: CF statement, financing activities; Forecast: = IS finance costs (assumed paid in the same year)
B16: FCF after interest | C16: =C14+C15 -> 2709 | D16: =D14+D15 -> 2166.26 | E16: =E14+E15 -> 1038.1 | F16: =F14+F15 -> 65 | G16: =G14+G15 -> 3769 | H16: =H14+H15 -> 3397.8393 | I16: =I14+I15 -> 5216.4005 | J16: =J14+J15 -> 6591.3394 | ... L16: =L14+L15 -> 9848.1769 | M16: FCF after interest — Calc: FCF − interest paid
B17: Acquisition | C17: 0 | D17: -19 | E17: 0 | F17: -10113 | G17: -53 | H17: 0 | I17: 0 | J17: 0 | K17: 0 | L17: 0 | M17: Acquisition — Hist: CF statement, acquisition of subsidiaries (FY25 = India Cements); Forecast: 0, no further acquisitions assumed
B18: Dividends paid | C18: -1065 | D18: -1091 | E18: -1094 | F18: -2012 | G18: -2273 | H18: =-Fin_Inputs!H12 -> -2858.2155 | I18: =-Fin_Inputs!I12 -> -3100.3529 | J18: =-Fin_Inputs!J12 -> -3596.6495 | K18: =-Fin_Inputs!K12 -> -3970.6913 | L18: =-Fin_Inputs!L12 -> -4328.1958 | M18: Dividends paid — Hist: CF statement, financing activities; Forecast: Fin_Inputs (35% of prior-year PAT to owners)
B19: Net borrowings | C19: -10171 | D19: 453 | E19: 330 | F19: 8859 | G19: -1466 | H19: =Debt!H7-Debt!H8 -> 0 | I19: =Debt!I7-Debt!I8 -> -2000 | J19: =Debt!J7-Debt!J8 -> -3000 | K19: =Debt!K7-Debt!K8 -> -4000 | L19: =Debt!L7-Debt!L8 -> -4000 | M19: Net borrowings — Hist: CF statement, proceeds − repayment of borrowings; Forecast: Debt sheet (new borrowings − repayment)
B20: Net change in cash | H20: =H16+H17+H18+H19 -> 539.62382 | I20: =I16+I17+I18+I19 -> 116.04757 | J20: =J16+J17+J18+J19 -> -5.3100574 | K20: =K16+K17+K18+K19 -> 1061.4223 | L20: =L16+L17+L18+L19 -> 1519.9811 | M20: Net change in cash — Calc (forecast only): FCF after interest + acquisitions + dividends + net borrowings; other investing/financing items assumed 0
B21: Opening cash | H21: =BS!G14 -> 1384 | I21: =H22 -> 1923.6238 | J21: =I22 -> 2039.6714 | K21: =J22 -> 2034.3613 | L21: =K22 -> 3095.7836 | M21: Opening cash — FY27E: BS FY26A cash; later years: prior-year closing cash
B22: Closing cash | H22: =H20+H21 -> 1923.6238 | I22: =I20+I21 -> 2039.6714 | J22: =J20+J21 -> 2034.3613 | K22: =K20+K21 -> 3095.7836 | L22: =L20+L21 -> 4615.7647 | M22: Closing cash — Calc: opening cash + net change; feeds BS cash
B24: RATIOS
B25: Cash conversion | C25: =C12/IS!C22 -> 0.80616587 | D25: =D12/IS!D22 -> 0.85393126 | E25: =E12/IS!E22 -> 0.84027681 | F25: =F12/IS!F22 -> 0.84996416 | G25: =G12/IS!G22 -> 0.8998016 | H25: =H12/IS!H22 -> 0.84146952 | I25: =I12/IS!I22 -> 0.84230438 | J25: =J12/IS!J22 -> 0.83916479 | ... L25: =L12/IS!L22 -> 0.81475966 | M25: Cash conversion — Calc: CFO ÷ operating EBITDA
B26: Capex/ revenue | C26: =-C13/IS!C7 -> 0.10671306 | D26: =-D13/IS!D7 -> 0.098046964 | E26: =-E13/IS!E7 -> 0.12700786 | F26: =-F13/IS!F7 -> 0.12018959 | G26: =-G13/IS!G7 -> 0.10934169 | H26: =-H13/IS!H7 -> 0.10097008 | I26: =-I13/IS!I7 -> 0.091008464 | J26: =-J13/IS!J7 -> 0.082742151 | ... L26: =-L13/IS!L7 -> 0.062188223 | M26: Capex / revenue — Calc: capex intensity
B27: Capex/ D&A | C27: =-C13/IS!C24 -> 2.0674033 | D27: =-D13/IS!D24 -> 2.1469841 | E27: =-E13/IS!E24 -> 2.863593 | F27: =-F13/IS!F24 -> 2.2737235 | G27: =-G13/IS!G24 -> 2.0839793 | H27: =-H13/IS!H24 -> 2.0013922 | I27: =-I13/IS!I24 -> 1.9005242 | J27: =-J13/IS!J24 -> 1.8139484 | ... L27: =-L13/IS!L24 -> 1.5222495 | M27: Capex / D&A — Calc: above 1x means the asset base is growing
B29: CHECKS
B30: Closing cash not negative | H30: =IF(H22<0,"ERROR","OK") -> OK | I30: =IF(I22<0,"ERROR","OK") -> OK | J30: =IF(J22<0,"ERROR","OK") -> OK | K30: =IF(K22<0,"ERROR","OK") -> OK | L30: =IF(L22<0,"ERROR","OK") -> OK | M30: Closing cash not negative — Check: flags a funding gap in any forecast year
B31: Closing cash vs BS cash | H31: =ROUND(H22-BS!H14,0) -> 0 | I31: =ROUND(I22-BS!I14,0) -> 0 | J31: =ROUND(J22-BS!J14,0) -> 0 | K31: =ROUND(K22-BS!K14,0) -> 0 | L31: =ROUND(L22-BS!L14,0) -> 0 | M31: Closing cash vs BS cash — Check: CF closing cash must equal BS cash

Sheet Ops_Data
B2: OPERATIONAL DATA
B3: Model status: | C3: =Check!E4 -> MODEL OK
C5: FY21A | D5: FY22A | E5: FY23A | F5: FY24A | G5: FY25A | H5: FY26A | I5: Sources
B6: HISTORICAL INPUTS
B7: Domestic capacity, year-end (mtpa) | C7: 111.35 | D7: 114.55 | E7: 126.95 | F7: 140.8 | G7: 183.4 | H7: 191.4 | I7: Domestic capacity, year-end (mtpa) — Q4 investor presentation of each year (capacity slide); FY21 from Q4 FY21 presentation
B8: Domestic grey volume, UltraTech only (mt) | D8: 87.25 | E8: 99.6 | F8: 112.23 | G8: 125.06 | H8: 140 | I8: Domestic grey volume, UltraTech only (mt) — Q4 investor presentations; FY25–26 exclude India Cements volumes
B9: Domestic grey volume, incl. ICL (mt) | D9: 87.25 | E9: 99.6 | F9: 112.23 | G9: 127.88 | H9: 145 | I9: Domestic grey volume, incl. ICL (mt) — Q4 investor presentations; same as UltraTech-only before ICL consolidation (Dec 2024)
B10: Consolidated sales volume (mt) | D10: 93.99 | E10: 105.7 | F10: 119.04 | G10: 135.83 | H10: 154.25 | I10: Consolidated sales volume (mt) — Q4 investor presentations (incl. white cement and overseas)
B11: UltraTech grey cement revenue, excl. ICL (₹ Cr) | D11: 44450 | E11: 53788 | F11: 59824 | G11: 62507 | H11: 70666 | I11: UltraTech grey cement revenue, excl. ICL (₹ Cr) — Q4 investor presentations
B13: FORMULAS
B14: Average capacity | D14: =(C7+D7)/2 -> 112.95 | E14: =(D7+E7)/2 -> 120.75 | F14: =(E7+F7)/2 -> 133.875 | G14: =(F7+G7)/2 -> 162.1 | H14: =(G7+H7)/2 -> 187.4 | I14: Average capacity — Calc: (opening + closing capacity) ÷ 2
B15: Utilisation (avg capacity) | D15: =D9/D14 -> 0.77246569 | E15: =E9/E14 -> 0.82484472 | F15: =F9/F14 -> 0.83831933 | G15: =G9/G14 -> 0.78889574 | H15: =H9/H14 -> 0.773746 | I15: Utilisation (avg capacity) — Calc: volume incl. ICL ÷ average capacity (capacity also includes ICL)
B16: Realisation (₹/t) | D16: =D11/D8*10 -> 5094.5559 | E16: =E11/E8*10 -> 5400.4016 | F16: =F11/F8*10 -> 5330.482 | G16: =G11/G8*10 -> 4998.1609 | H16: =H11/H8*10 -> 5047.5714 | I16: Realisation (₹/t) — Calc: grey revenue excl. ICL ÷ UltraTech-only volume × 10
B17: Revenue per tonne (₹/t) | D17: =IS!C7/Ops_Data!D10*10 -> 5596.2336 | E17: =IS!D7/Ops_Data!E10*10 -> 5982.9707 | F17: =IS!E7/Ops_Data!F10*10 -> 5956.7372 | G17: =IS!F7/Ops_Data!G10*10 -> 5591.9164 | H17: =IS!G7/Ops_Data!H10*10 -> 5738.1867 | I17: Revenue per tonne (₹/t) — Calc: IS revenue ÷ consolidated volume × 10
B18: Operating EBITDA per tonne (₹/t) | D18: =IS!C22/Ops_Data!D10*10 -> 1225.1303 | E18: =IS!D22/Ops_Data!E10*10 -> 1004.7304 | F18: =IS!E22/Ops_Data!F10*10 -> 1089.4657 | G18: =IS!F22/Ops_Data!G10*10 -> 924.4644 | H18: =IS!G22/Ops_Data!H10*10 -> 1103.5028 | I18: Operating EBITDA per tonne (₹/t) — Calc: IS operating EBITDA ÷ consolidated volume × 10

Sheet Ops_Forecast
B2: OPERATIONAL FORECAST
B3: Model status: | C3: =Check!E4 -> MODEL OK
C5: FY22A | D5: FY23A | E5: FY24A | F5: FY25A | G5: FY26A | H5: FY27E | I5: FY28E | J5: FY29E | K5: FY30E | L5: FY31E | M5: Source/ Reason
B6: FORECAST ASSUMPTIONS
B7: Domestic capacity, year-end (mtpa) | C7: =Ops_Data!D7 -> 114.55 | D7: =Ops_Data!E7 -> 126.95 | E7: =Ops_Data!F7 -> 140.8 | F7: =Ops_Data!G7 -> 183.4 | G7: =Ops_Data!H7 -> 191.4 | H7: =G7+H8 -> 207.3 | I7: =H7+I8 -> 237.1 | J7: =I7+J8 -> 245.1 | K7: =J7+K8 -> 253.1 | L7: =K7+L8 -> 261.1 | M7: Hist: Ops_Data (company Q4 decks, FY22 AR). Fcst: last year + additions
B8: Capacity additions (mtpa) | D8: =D7-C7 -> 12.4 | E8: =E7-D7 -> 13.85 | F8: =F7-E7 -> 42.6 | G8: =G7-F7 -> 8 | H8: 15.9 | I8: 29.8 | J8: 8 | K8: 8 | L8: 8 | M8: Hist: actual additions (FY25 incl. ~25 mtpa acquired: India Cements + Kesoram). FY27-28: company guidance, Q4 FY26 deck (plants under construction). FY29-31: ~8 mtpa/yr, in line with UltraTech's historical organic pace
B9: Domestic volume growth (%) | D9: =D21/C21-1 -> 0.14154728 | E9: =E21/D21-1 -> 0.12680723 | F9: =F21/E21-1 -> 0.13944578 | G9: =G21/F21-1 -> 0.13387551 | H9: 0.1 | I9: 0.09 | J9: 0.08 | K9: 0.07 | L9: 0.07 | M9: Hist incl. acquisitions (ICL from Dec-24), so not organic. Fcst: industry demand 7-8% FY27, 8-9% FY28 (ICRA Feb-26) + share gains; Q1 FY27 actual +13.1%. Fades to ~7% (industry rate) by FY30-31
B10: Other volume growth (%) | D10: =D23/C23-1 -> -0.09495549 | E10: =E23/D23-1 -> 0.11639344 | F10: =F23/E23-1 -> 0.16740088 | G10: =G23/F23-1 -> 0.16352201 | H10: 0.05 | I10: 0.05 | J10: 0.05 | K10: 0.05 | L10: 0.05 | M10: Hist volatile and acquisition-driven (UAE white cement subsidiary FY25); UAE ops disrupted Q1 FY27. Fcst: conservative 5%. Only ~6% of total volume, low valuation impact
B11: Revenue per tonne growth (%) | D11: =D27/C27-1 -> 0.069106663 | E11: =E27/D27-1 -> -0.0043846848 | F11: =F27/E27-1 -> -0.061245083 | G11: =G27/F27-1 -> 0.026157463 | H11: 0.02 | I11: 0.02 | J11: 0.02 | K11: 0.02 | L11: 0.02 | M11: Hist: revenue/t CAGR only 0.6% FY22-26 vs ~5% inflation (industry oversupply). Fcst: 2% = some benefit from industry consolidation, capped by ~100 mtpa new industry capacity by FY28. Bear 0% / Bull 4%
B12: Raw materials per tonne growth | D12: =D33/C33-1 -> 0.084585233 | E12: =E33/D33-1 -> 0.087916836 | F12: =F33/E33-1 -> 0.0089929549 | G12: =G33/F33-1 -> 0.10445626 | H12: 0.05 | I12: 0.05 | J12: 0.05 | K12: 0.05 | L12: 0.05 | M12: Hist: actual Rs/t growth (Hist_IS). FY22-26 CAGR ~7% incl. mix shift (more blended cement, RMC, traded goods). Fcst 5%: ~inflation, mix shift slowing. Biggest driver of margin squeeze FY26-31
B13: Power & fuel per tonne growth | D13: =D34/C34-1 -> 0.35473924 | E13: =E34/D34-1 -> -0.12205132 | F13: =F34/E34-1 -> -0.11709128 | G13: =G34/F34-1 -> -0.063098201 | H13: 0.04 | I13: 0 | J13: 0.02 | K13: 0.02 | L13: 0.02 | M13: Hist: FY23 +35% = Russia-Ukraine coal/petcoke spike, then normalised. FY27 +4%: West Asia fuel spike in Q1 (Ramco P&F/t +8.5%, Shree EBITDA/t -25%), easing from Q2. FY28 0%: prices normalise + green power (47% at Q1 FY27). FY29+ 2%: green power/WHRS offset inflation. Sensitivity: +$10/t imported fuel = -Rs60-70/t EBITDA
B14: Freight per tonne growth | D14: =D35/C35-1 -> 0.063610789 | E14: =E35/D35-1 -> 0.0065903894 | F14: =F35/E35-1 -> -0.036473616 | G14: =G35/F35-1 -> -0.033224255 | H14: 0.02 | I14: 0.01 | J14: 0.01 | K14: 0.01 | L14: 0.01 | M14: Hist: ~flat (CAGR -0.1%) despite diesel inflation, due to lower lead distance, more rail, bulk terminals. FY27 2%: diesel price hikes (JK Cement Q1 FY27 call). FY28+ 1%: efficiency offsets most inflation
B15: Other expenses per tonne growth | D15: =D37/C37-1 -> 0.012133681 | E15: =E37/D37-1 -> 0.023339665 | F15: =F37/E37-1 -> 0.012783007 | G15: =G37/F37-1 -> -0.019024841 | H15: 0.03 | I15: 0.03 | J15: 0.03 | K15: 0.03 | L15: 0.03 | M15: Hist: ~flat to +2%/yr (packing, stores & spares = variable; admin = fixed). Fcst 3%: slightly below inflation
B16: Employee cost growth (total ₹ Cr) | D16: =IS!D15/IS!C15-1 -> 0.080473373 | E16: =IS!E15/IS!D15-1 -> 0.10916393 | F16: =IS!F15/IS!E15-1 -> 0.18663594 | G16: =IS!G15/IS!F15-1 -> 0.15450763 | H16: 0.08 | I16: 0.08 | J16: 0.08 | K16: 0.08 | L16: 0.08 | M16: Hist: total growth 8-11% organic (FY23-24); FY25-26 inflated by acquisitions. Fcst 8%: wage inflation + staff for new plants. Grown in total (fixed cost) so Rs/t falls as volume grows = operating leverage
B17: Utilisation trigger | H17: 0.85 | I17: 0.85 | J17: 0.85 | K17: 0.85 | L17: 0.85
B19: VOLUME
B20: Average capacity (mtpa) | C20: =Ops_Data!D14 -> 112.95 | D20: =Ops_Data!E14 -> 120.75 | E20: =Ops_Data!F14 -> 133.875 | F20: =Ops_Data!G14 -> 162.1 | G20: =Ops_Data!H14 -> 187.4 | H20: =(G7+H7)/2 -> 199.35 | I20: =(H7+I7)/2 -> 222.2 | J20: =(I7+J7)/2 -> 241.1 | K20: =(J7+K7)/2 -> 249.1 | L20: =(K7+L7)/2 -> 257.1 | M20: (Opening + closing capacity) / 2. Plants start mid-year, so average reflects capacity actually available
B21: Domestic grey volume, incl. ICL (mt) | C21: =Ops_Data!D9 -> 87.25 | D21: =Ops_Data!E9 -> 99.6 | E21: =Ops_Data!F9 -> 112.23 | F21: =Ops_Data!G9 -> 127.88 | G21: =Ops_Data!H9 -> 145 | H21: =G21*(1+H9) -> 159.5 | I21: =H21*(1+I9) -> 173.855 | J21: =I21*(1+J9) -> 187.7634 | K21: =J21*(1+K9) -> 200.90684 | L21: =K21*(1+L9) -> 214.97032 | M21: Hist: Ops_Data (incl. India Cements from FY25). Fcst: last year x (1 + domestic volume growth)
B22: Utilisation (%) | C22: =C21/C20 -> 0.77246569 | D22: =D21/D20 -> 0.82484472 | E22: =E21/E20 -> 0.83831933 | F22: =F21/F20 -> 0.78889574 | G22: =G21/G20 -> 0.773746 | H22: =H21/H20 -> 0.80010033 | I22: =I21/I20 -> 0.78242574 | J22: =J21/J20 -> 0.7787781 | ... L22: =L21/L20 -> 0.83613503 | M22: Domestic volume / average capacity. Company reported ~78% FY25. Healthy range 75-85%
B23: Other volume (mt) | C23: =Ops_Data!D10-Ops_Forecast!C21 -> 6.74 | D23: =Ops_Data!E10-Ops_Forecast!D21 -> 6.1 | E23: =Ops_Data!F10-Ops_Forecast!E21 -> 6.81 | F23: =Ops_Data!G10-Ops_Forecast!F21 -> 7.95 | G23: =Ops_Data!H10-Ops_Forecast!G21 -> 9.25 | H23: =G23*(1+H10) -> 9.7125 | I23: =H23*(1+I10) -> 10.198125 | J23: =I23*(1+J10) -> 10.708031 | K23: =J23*(1+K10) -> 11.243433 | L23: =K23*(1+L10) -> 11.805604 | M23: domestic grey volume (white cement, overseas, exports). Fcst: last year x (1 + other volume growth)
B24: Consolidated volume (mt) | C24: =C21+C23 -> 93.99 | D24: =D21+D23 -> 105.7 | E24: =E21+E23 -> 119.04 | F24: =F21+F23 -> 135.83 | G24: =G21+G23 -> 154.25 | H24: =H21+H23 -> 169.2125 | I24: =I21+I23 -> 184.05313 | J24: =J21+J23 -> 198.47143 | ... L24: =L21+L23 -> 226.77592 | M24: Domestic + other volume. Hist ties to Ops_Data consolidated sales volume
B26: REVENUE
B27: Revenue per tonne (₹/t) | C27: =Ops_Data!D17 -> 5596.2336 | D27: =Ops_Data!E17 -> 5982.9707 | E27: =Ops_Data!F17 -> 5956.7372 | F27: =Ops_Data!G17 -> 5591.9164 | G27: =Ops_Data!H17 -> 5738.1867 | H27: =G27*(1+H11) -> 5852.9504 | I27: =H27*(1+I11) -> 5970.0095 | J27: =I27*(1+J11) -> 6089.4096 | K27: =J27*(1+K11) -> 6211.1978 | L27: =K27*(1+L11) -> 6335.4218 | M27: Hist: Ops_Data (Hist_IS revenue / consolidated volume). Fcst: last year x (1 + revenue/t growth). Blended price incl. RMC and white cement
B28: Revenue (₹ Cr) | C28: =C24*C27/10 -> 52599 | D28: =D24*D27/10 -> 63240 | E28: =E24*E27/10 -> 70909 | F28: =F24*F27/10 -> 75955 | G28: =G24*G27/10 -> 88511.53 | H28: =H24*H27/10 -> 99039.238 | I28: =I24*I27/10 -> 109879.89 | J28: =J24*J27/10 -> 120857.38 | ... L28: =L24*L27/10 -> 143672.11 | M28: Consolidated volume x revenue per tonne / 10 (mt x Rs/t = Rs mn; /10 = Rs Cr)
B29: Revenue growth (%) | D29: =D28/C28-1 -> 0.20230423 | E29: =E28/D28-1 -> 0.12126818 | F29: =F28/E28-1 -> 0.07116163 | G29: =G28/F28-1 -> 0.16531538 | H29: =H28/G28-1 -> 0.11894165 | I29: =I28/H28-1 -> 0.10945815 | J29: =J28/I28-1 -> 0.099904497 | K29: =K28/J28-1 -> 0.090299369 | L29: =L28/K28-1 -> 0.090318851 | M29: Revenue growth ~ volume growth + price growth (FY27: ~10% + 2% = ~12%)
B31: COSTS
B32: Employee cost (₹ Cr) | C32: =IS!C15 -> 2535 | D32: =IS!D15 -> 2739 | E32: =IS!E15 -> 3038 | F32: =IS!F15 -> 3605 | G32: =IS!G15 -> 4162 | H32: =G32*(1+H16) -> 4494.96 | I32: =H32*(1+I16) -> 4854.5568 | J32: =I32*(1+J16) -> 5242.9213 | K32: =J32*(1+K16) -> 5662.3551 | L32: =K32*(1+L16) -> 6115.3435 | M32: Hist: Hist_IS employee benefits expense. Fcst: last year x (1 + employee cost growth). Fixed cost, forecast in total
B33: Raw materials per tonne (₹/t) | C33: =(IS!C12+IS!C13+IS!C14)*10/Ops_Forecast!C24 -> 847.43058 | D33: =(IS!D12+IS!D13+IS!D14)*10/Ops_Forecast!D24 -> 919.11069 | E33: =(IS!E12+IS!E13+IS!E14)*10/Ops_Forecast!E24 -> 999.91599 | F33: =(IS!F12+IS!F13+IS!F14)*10/Ops_Forecast!F24 -> 1008.9082 | G33: =(IS!G12+IS!G13+IS!G14)*10/Ops_Forecast!G24 -> 1114.295 | H33: =G33*(1+H12) -> 1170.0097 | I33: =H33*(1+I12) -> 1228.5102 | J33: =I33*(1+J12) -> 1289.9357 | K33: =J33*(1+K12) -> 1354.4325 | L33: =K33*(1+L12) -> 1422.1541 | M33: (Cost of materials + Purchases of stock-in-trade + Change in inventories) x 10 / consolidated volume. Fcst: last year x (1 + growth)
B34: Power & fuel per tonne (₹/t) | C34: =(IS!C16)*10/Ops_Forecast!C24 -> 1291.3076 | D34: =(IS!D16)*10/Ops_Forecast!D24 -> 1749.3851 | E34: =(IS!E16)*10/Ops_Forecast!E24 -> 1535.8703 | F34: =(IS!F16)*10/Ops_Forecast!F24 -> 1356.0333 | G34: =(IS!G16)*10/Ops_Forecast!G24 -> 1270.47 | H34: =G34*(1+H13) -> 1321.2888 | I34: =H34*(1+I13) -> 1321.2888 | J34: =I34*(1+J13) -> 1347.7146 | K34: =J34*(1+K13) -> 1374.6689 | L34: =K34*(1+L13) -> 1402.1623 | M34: Power & fuel x 10 / consolidated volume. Fcst: last year x (1 + growth)
B35: Freight per tonne (₹/t) | C35: =(IS!C17)*10/Ops_Forecast!C24 -> 1246.09 | D35: =(IS!D17)*10/Ops_Forecast!D24 -> 1325.3548 | E35: =(IS!E17)*10/Ops_Forecast!E24 -> 1334.0894 | F35: =(IS!F17)*10/Ops_Forecast!F24 -> 1285.4303 | G35: =(IS!G17)*10/Ops_Forecast!G24 -> 1242.7229 | H35: =G35*(1+H14) -> 1267.5773 | I35: =H35*(1+I14) -> 1280.2531 | J35: =I35*(1+J14) -> 1293.0556 | K35: =J35*(1+K14) -> 1305.9862 | L35: =K35*(1+L14) -> 1319.046 | M35: Freight & forwarding x 10 / consolidated volume. Fcst: last year x (1 + growth)
B36: Employee per tonne (₹/t) | C36: =C32/C24*10 -> 269.70954 | D36: =D32/D24*10 -> 259.12961 | E36: =E32/E24*10 -> 255.20833 | F36: =F32/F24*10 -> 265.40529 | G36: =G32/G24*10 -> 269.82172 | H36: =H32/H24*10 -> 265.63995 | I36: =I32/I24*10 -> 263.75846 | J36: =J32/J24*10 -> 264.16504 | ... L36: =L32/L24*10 -> 269.66458 | M36: Employee cost (Rs Cr) x 10 / consolidated volume. Same formula all years. Falls when volume growth > 8% (operating leverage)
B37: Other expenses per tonne (₹/t) | C37: =(IS!C18)*10/Ops_Forecast!C24 -> 716.56559 | D37: =(IS!D18)*10/Ops_Forecast!D24 -> 725.26017 | E37: =(IS!E18)*10/Ops_Forecast!E24 -> 742.1875 | F37: =(IS!F18)*10/Ops_Forecast!F24 -> 751.67489 | G37: =(IS!G18)*10/Ops_Forecast!G24 -> 737.37439 | H37: =G37*(1+H15) -> 759.49562 | I37: =H37*(1+I15) -> 782.28049 | J37: =I37*(1+J15) -> 805.74891 | K37: =J37*(1+K15) -> 829.92137 | L37: =K37*(1+L15) -> 854.81902 | M37: Other expenses x 10 / consolidated volume. Fcst: last year x (1 + growth)
B38: Total cost per tonne (₹/t) | C38: =SUM(C33:C37) -> 4371.1033 | D38: =SUM(D33:D37) -> 4978.2403 | E38: =SUM(E33:E37) -> 4867.2715 | F38: =SUM(F33:F37) -> 4667.452 | G38: =SUM(G33:G37) -> 4634.684 | H38: =SUM(H33:H37) -> 4784.0114 | I38: =SUM(I33:I37) -> 4876.0911 | J38: =SUM(J33:J37) -> 5000.6199 | ... L38: =SUM(L33:L37) -> 5267.846 | M38: Sum of five costs per tonne
B39: Operating EBITDA per tonne (₹/t) | C39: =C27-C38 -> 1225.1303 | D39: =D27-D38 -> 1004.7304 | E39: =E27-E38 -> 1089.4657 | F39: =F27-F38 -> 924.4644 | G39: =G27-G38 -> 1103.5028 | H39: =H27-H38 -> 1068.939 | I39: =I27-I38 -> 1093.9184 | J39: =J27-J38 -> 1088.7898 | ... L39: =L27-L38 -> 1067.5758 | M39: Total cost/t. Ties to Ops_Data. Base case stays above CRISIL's Rs1,050/t floor (Rating rationale, Jul-26)
B41: EBITDA
B42: Total operating costs (₹ Cr) | C42: =C38*C24/10 -> 41084 | D42: =D38*D24/10 -> 52620 | E42: =E38*E24/10 -> 57940 | F42: =F38*F24/10 -> 63398 | G42: =G38*G24/10 -> 71490 | H42: =H38*H24/10 -> 80951.453 | I42: =I38*I24/10 -> 89745.98 | J42: =J38*J24/10 -> 99248.018 | ... L42: =L38*L24/10 -> 119462.06 | M42: Total cost per tonne x consolidated volume / 10. Ties to Hist_IS total operating expenses
B43: Operating EBITDA (₹ Cr) | C43: =C28-C42 -> 11515 | D43: =D28-D42 -> 10620 | E43: =E28-E42 -> 12969 | F43: =F28-F42 -> 12557 | G43: =G28-G42 -> 17021.53 | H43: =H28-H42 -> 18087.784 | I43: =I28-I42 -> 20133.91 | J43: =J28-J42 -> 21609.366 | ... L43: =L28-L42 -> 24210.048 | M43: Total operating costs. Excludes other income (non-operating; added back on the forecast income statement)
B44: Operating EBITDA margin (%) | C44: =C43/C28 -> 0.21892051 | D44: =D43/D28 -> 0.16793169 | E44: =E43/E28 -> 0.18289639 | F44: =F43/F28 -> 0.16532157 | G44: =G43/G28 -> 0.19230862 | H44: =H43/H28 -> 0.18263251 | I44: =I43/I28 -> 0.18323562 | J44: =J43/J28 -> 0.17880055 | ... L44: =L43/L28 -> 0.16850903 | M44: Operating EBITDA / Revenue. Falls 19.2% (FY26) to 16.9% (FY31): price +2%/yr vs costs ~2.6%/yr
B45: EBITDA growth (%) | D45: =D43/C43-1 -> -0.077724707 | E45: =E43/D43-1 -> 0.22118644 | F45: =F43/E43-1 -> -0.031768062 | G45: =G43/F43-1 -> 0.35554113 | H45: =H43/G43-1 -> 0.062641512 | I45: =I43/H43-1 -> 0.11312195 | J45: =J43/I43-1 -> 0.073282162 | K45: =K43/J43-1 -> 0.059590481 | L45: =L43/K43-1 -> 0.057342199 | M45: FY27 low (6.3%) due to Q1 fuel spike; FY28 rebound (11.3%) as fuel normalises; then fades with volume growth
B47: CHECKS
...

Sheet Capex_DA
B2: CAPITAL EXPENDITURE
B3: Model status: | C3: =Check!E4 -> MODEL OK
C5: FY22A | D5: FY23A | E5: FY24A | F5: FY25A | G5: FY26A | H5: FY27E | I5: FY28E | J5: FY29E | K5: FY30E | L5: FY31E | M5: Source/ Reason
B6: INPUT
B7: Capex guidance (₹ Cr) | H7: 10000 | I7: 10000 | J7: 10000 | K7: 0 | L7: 0 | M7: FY27-29: mgmt guidance ~Rs10,000 Cr/yr (Q2 FY26 call); CRISIL ~Rs30,000 Cr FY27-29 (rating rationale, Aug-26). FY30-31 blank: no guidance, driver-based
B8: Cost per mtpa of new capacity (₹ Cr) | H8: 600 | I8: 600 | J8: 600 | K8: 600 | L8: 600 | M8: Rs600 Cr/mtpa: CRISIL Rs30,000 Cr for ~37 mtpa less maintenance. Cross-check: UltraTech Phase IV Rs10,255 Cr for 22.8 mtpa (~Rs450 Cr/mtpa). Used for FY30-31 only
B9: Maintenance capex per tonne (₹/t) | H9: 150 | I9: =H9*(1+I10) -> 157.5 | J9: =I9*(1+J10) -> 165.375 | K9: =J9*(1+K10) -> 173.64375 | L9: =K9*(1+L10) -> 182.32594 | M9: Analyst estimate (not disclosed): ~half of FY26 D&A per tonne (Rs301/t). Common rule of thumb for a young asset base
B10: Maintenance capex per tonne growth (%) | I10: 0.05 | J10: 0.05 | K10: 0.05 | L10: 0.05 | M10: 5%: maintenance cost grows with inflation
B11: Depreciation rate (%) | H11: 0.053 | I11: 0.053 | J11: 0.053 | K11: 0.053 | L11: 0.053 | M11: 5.3%: FY26 actual D&A / (opening PPE + 50% capex). FY25 (6.4%) excluded: D&A included acquired plants not in opening PPE
B12: Share of capex depreciated in year 1 (%) | D12: 0.5 | E12: 0.5 | F12: 0.5 | G12: 0.5 | H12: 0.5 | I12: 0.5 | J12: 0.5 | K12: 0.5 | L12: 0.5 | M12: 50%: capex spent through the year, so on average in service for half the year. Avoids circularity of depreciating average PPE
B13: Other PPE movements (₹ Cr) | H13: 0 | I13: 0 | J13: 0 | K13: 0 | L13: 0 | M13: 0: no acquisitions assumed. Historical spike FY25 (+Rs20,100 Cr) = India Cements + Kesoram
B15: CAPEX & DEPRECIATION
B16: Capacity additions (mtpa) | D16: =Ops_Forecast!D8 -> 12.4 | E16: =Ops_Forecast!E8 -> 13.85 | F16: =Ops_Forecast!F8 -> 42.6 | G16: =Ops_Forecast!G8 -> 8 | H16: =Ops_Forecast!H8 -> 15.9 | I16: =Ops_Forecast!I8 -> 29.8 | J16: =Ops_Forecast!J8 -> 8 | K16: =Ops_Forecast!K8 -> 8 | L16: =Ops_Forecast!L8 -> 8 | M16: Link: Ops_Forecast capacity additions. FY25 (42.6) includes ~26 mtpa acquired
B17: Maintenance capex (₹ Cr) | H17: =Ops_Forecast!H24*Capex_DA!H9/10 -> 2538.1875 | I17: =Ops_Forecast!I24*Capex_DA!I9/10 -> 2898.8367 | J17: =Ops_Forecast!J24*Capex_DA!J9/10 -> 3282.2213 | K17: =Ops_Forecast!K24*Capex_DA!K9/10 -> 3683.8569 | L17: =Ops_Forecast!L24*Capex_DA!L9/10 -> 4134.7132 | M17: Volume (Ops_Forecast) x maintenance capex/t / 10. Not disclosed historically, so history blank
B18: Growth capex (₹ Cr) | H18: =IF(H7>0,H7-H17,H16*H8) -> 7461.8125 | I18: =IF(I7>0,I7-I17,I16*I8) -> 7101.1633 | J18: =IF(J7>0,J7-J17,J16*J8) -> 6717.7787 | K18: =IF(K7>0,K7-K17,K16*K8) -> 4800 | L18: =IF(L7>0,L7-L17,L16*L8) -> 4800 | M18: maintenance; else additions x cost per mtpa
B19: Capex (₹ Cr) | C19: =-CF!C13 -> 5613 | D19: =-CF!D13 -> 6200.49 | E19: =-CF!E13 -> 9006 | F19: =-CF!F13 -> 9129 | G19: =-CF!G13 -> 9678 | H19: =H17+H18 -> 10000 | I19: =I17+I18 -> 10000 | J19: =J17+J18 -> 10000 | K19: =K17+K18 -> 8483.8569 | L19: =L17+L18 -> 8934.7132 | M19: Hist: Hist_CF purchase of PPE (positive here). Fcst: maintenance + growth. Falls after FY29 as expansion completes
B20: Depreciation base (₹ Cr) | D20: =D27+(D12*D19) -> 51648.245 | E20: =E27+(E12*E19) -> 56209 | F20: =F27+(F12*F19) -> 62389.5 | G20: =G27+(G12*G19) -> 87878 | H20: =H27+(H12*H19) -> 94274 | I20: =I27+(I12*I19) -> 99277.478 | J20: =J27+(J12*J19) -> 104015.77 | K20: =K27+(K12*K19) -> 107744.86 | L20: =L27+(L12*L19) -> 110743.67 | M20: Opening PPE + 50% x capex. Replaces average PPE to avoid circular reference
B21: Depreciation rate (%) | D21: =D22/D20 -> 0.055916711 | E21: =E22/E20 -> 0.055951894 | F21: =F22/F20 -> 0.064353777 | G21: =G22/G20 -> 0.052845991 | H21: =H11 -> 0.053 | I21: =I11 -> 0.053 | J21: =J11 -> 0.053 | K21: =K11 -> 0.053 | L21: =L11 -> 0.053 | M21: Hist: D&A / depreciation base. Fcst: input (5.3%)
B22: Depreciation & amortisation (₹ Cr) | C22: =IS!C24 -> 2715 | D22: =IS!D24 -> 2888 | E22: =IS!E24 -> 3145 | F22: =IS!F24 -> 4015 | G22: =IS!G24 -> 4644 | H22: =H20*H21 -> 4996.522 | I22: =I20*I21 -> 5261.7063 | J22: =J20*J21 -> 5512.8359 | K22: =K20*K21 -> 5710.4778 | L22: =L20*L21 -> 5869.4146 | M22: Hist: Hist_IS. Fcst: depreciation base x rate. Rises as new plants are commissioned (non-cash)
B23: PPE, closing (₹ Cr) | C23: =BS!C7 -> 48548 | D23: =BS!D7 -> 51706 | E23: =BS!E7 -> 57825 | F23: =BS!F7 -> 83039 | G23: =BS!G7 -> 89274 | H23: =H30+H31 -> 94277.478 | I23: =I30+I31 -> 99015.772 | J23: =J30+J31 -> 103502.94 | K23: =K30+K31 -> 106276.31 | L23: =L30+L31 -> 109341.61 | M23: Hist: Hist_BS (PPE incl. CWIP, ROU). Fcst: expected closing + other movements
B24: Capex / D&A (x) | C24: =C19/C22 -> 2.0674033 | D24: =D19/D22 -> 2.1469841 | E24: =E19/E22 -> 2.863593 | F24: =F19/F22 -> 2.2737235 | G24: =G19/G22 -> 2.0839793 | H24: =H19/H22 -> 2.0013922 | I24: =I19/I22 -> 1.9005242 | J24: =J19/J22 -> 1.8139484 | ... L24: =L19/L22 -> 1.5222495 | M24: Capex / D&A. Above 1x = growing asset base; falls 2.1x to 1.5x as expansion matures
B26: PPE ROLL-FORWARD
B27: Opening PPE | D27: =C23 -> 48548 | E27: =D23 -> 51706 | F27: =E23 -> 57825 | G27: =F23 -> 83039 | H27: =G23 -> 89274 | I27: =H23 -> 94277.478 | J27: =I23 -> 99015.772 | K27: =J23 -> 103502.94 | L27: =K23 -> 106276.31 | M27: Previous year's closing PPE
B28: + Capex | D28: =D19 -> 6200.49 | E28: =E19 -> 9006 | F28: =F19 -> 9129 | G28: =G19 -> 9678 | H28: =H19 -> 10000 | I28: =I19 -> 10000 | J28: =J19 -> 10000 | K28: =K19 -> 8483.8569 | L28: =L19 -> 8934.7132 | M28: Capex row
B29: − D&A | D29: =-D22 -> -2888 | E29: =-E22 -> -3145 | F29: =-F22 -> -4015 | G29: =-G22 -> -4644 | H29: =-H22 -> -4996.522 | I29: =-I22 -> -5261.7063 | J29: =-J22 -> -5512.8359 | K29: =-K22 -> -5710.4778 | L29: =-L22 -> -5869.4146 | M29: D&A row (negative)
B30: Expected closing PPE | D30: =SUM(D27:D29) -> 51860.49 | E30: =SUM(E27:E29) -> 57567 | F30: =SUM(F27:F29) -> 62939 | G30: =SUM(G27:G29) -> 88073 | H30: =SUM(H27:H29) -> 94277.478 | I30: =SUM(I27:I29) -> 99015.772 | J30: =SUM(J27:J29) -> 103502.94 | K30: =SUM(K27:K29) -> 106276.31 | L30: =SUM(L27:L29) -> 109341.61 | M30: D&A
B31: Other movements | D31: =D23-D30 -> -154.49 | E31: =E23-E30 -> 258 | F31: =F23-F30 -> 20100 | G31: =G23-G30 -> 1201 | H31: =H13 -> 0 | I31: =I13 -> 0 | J31: =J13 -> 0 | K31: =K13 -> 0 | L31: =L13 -> 0 | M31: expected (FY25 +Rs20,100 Cr = acquisitions). Fcst: link to input (0)
B33: CHECKS
B34: PPE roll-forward check | D34: =ROUND(D23-D30-D31,0) -> 0 | E34: =ROUND(E23-E30-E31,0) -> 0 | F34: =ROUND(F23-F30-F31,0) -> 0 | G34: =ROUND(G23-G30-G31,0) -> 0 | H34: =ROUND(H23-H30-H31,0) -> 0 | I34: =ROUND(I23-I30-I31,0) -> 0 | J34: =ROUND(J23-J30-J31,0) -> 0 | K34: =ROUND(K23-K30-K31,0) -> 0 | L34: =ROUND(L23-L30-L31,0) -> 0 | M34: other movements, 0). Must be 0 in all years

Sheet WC
B2: WORKING CAPITAL
B3: Model status: | C3: =Check!E4 -> MODEL OK
C5: FY22A | D5: FY23A | E5: FY24A | F5: FY25A | G5: FY26A | H5: FY27E | I5: FY28E | J5: FY29E | K5: FY30E | L5: FY31E | M5: Source/ Reason
B6: INPUT
B7: Receivable days | H7: 24 | I7: 23 | J7: 22 | K7: 22 | L7: 22 | M7: Hist 21-22 pre-acquisition; 28.3 FY25 (ICL acquired with weak collections; year-end balances vs part-year revenue); improving to 24.9 FY26 as ICL moves to UltraTech terms. Fcst: 24 to 22, back to pre-acquisition norm
B8: Inventory days | H8: 40 | I8: 40 | J8: 40 | K8: 40 | L8: 40 | M8: Hist 38-43; FY25 46 acquisition-distorted (excluded). Fcst 40: FY26 actual and ~5-yr average. Cement can't be stored long
B9: Payable days | H9: 42 | I9: 42 | J9: 42 | K9: 42 | L9: 42 | M9: Hist 41-45, steady. Fcst 42: FY26 actual. Suppliers fund most of inventory
B11: WORKING CAPITAL
B12: Revenue (₹ Cr) | C12: =Ops_Forecast!C28 -> 52599 | D12: =Ops_Forecast!D28 -> 63240 | E12: =Ops_Forecast!E28 -> 70909 | F12: =Ops_Forecast!F28 -> 75955 | G12: =Ops_Forecast!G28 -> 88511.53 | H12: =Ops_Forecast!H28 -> 99039.238 | I12: =Ops_Forecast!I28 -> 109879.89 | J12: =Ops_Forecast!J28 -> 120857.38 | ... L12: =Ops_Forecast!L28 -> 143672.11 | M12: Link: Ops_Forecast revenue (all 10 years)
B13: Trade receivables (₹ Cr) | C13: =BS!C13 -> 3072 | D13: =BS!D13 -> 3867 | E13: =BS!E13 -> 4278 | F13: =BS!F13 -> 5890 | G13: =BS!G13 -> 6029 | H13: =H7*H12/365 -> 6512.1691 | I13: =I7*I12/365 -> 6923.9382 | J13: =J7*J12/365 -> 7284.5547 | K13: =K7*K12/365 -> 7942.3454 | L13: =L7*L12/365 -> 8659.6889 | M13: Hist: Hist_BS. Fcst: receivable days x revenue / 365
B14: Inventories (₹ Cr) | C14: =BS!C12 -> 5596 | D14: =BS!D12 -> 6612 | E14: =BS!E12 -> 8330 | F14: =BS!F12 -> 9563 | G14: =BS!G12 -> 9694 | H14: =H8*H12/365 -> 10853.615 | I14: =I8*I12/365 -> 12041.632 | J14: =J8*J12/365 -> 13244.645 | K14: =K8*K12/365 -> 14440.628 | L14: =L8*L12/365 -> 15744.889 | M14: Hist: Hist_BS. Fcst: inventory days x revenue / 365
B15: Trade payables (₹ Cr) | C15: =BS!C29 -> 5863 | D15: =BS!D29 -> 7208.5 | E15: =BS!E29 -> 8477.75 | F15: =BS!F29 -> 9327 | G15: =BS!G29 -> 10237 | H15: =H9*H12/365 -> 11396.296 | I15: =I9*I12/365 -> 12643.713 | J15: =J9*J12/365 -> 13906.877 | K15: =K9*K12/365 -> 15162.659 | L15: =L9*L12/365 -> 16532.133 | M15: Hist: Hist_BS. Fcst: payable days x revenue / 365
B16: Trade working capital (₹ Cr) | C16: =C13+C14-C15 -> 2805 | D16: =D13+D14-D15 -> 3270.5 | E16: =E13+E14-E15 -> 4130.25 | F16: =F13+F14-F15 -> 6126 | G16: =G13+G14-G15 -> 5486 | H16: =H13+H14-H15 -> 5969.4883 | I16: =I13+I14-I15 -> 6321.8567 | J16: =J13+J14-J15 -> 6622.3224 | ... L16: =L13+L14-L15 -> 7872.4445 | M16: payables. ~6% of revenue: low for a manufacturer
B17: Receivable days | C17: =C13/C12*365 -> 21.317516 | D17: =D13/D12*365 -> 22.319023 | E17: =E13/E12*365 -> 22.020759 | F17: =F13/F12*365 -> 28.304259 | G17: =G13/G12*365 -> 24.862128 | H17: =H13/H12*365 -> 24 | I17: =I13/I12*365 -> 23 | J17: =J13/J12*365 -> 22 | ... L17: =L13/L12*365 -> 22 | M17: Receivables / revenue x 365 (revenue basis, consistent with forecast)
B18: Inventory days | C18: =C14/C12*365 -> 38.832297 | D18: =D14/D12*365 -> 38.162239 | E18: =E14/E12*365 -> 42.878196 | F18: =F14/F12*365 -> 45.954776 | G18: =G14/G12*365 -> 39.975696 | H18: =H14/H12*365 -> 40 | I18: =I14/I12*365 -> 40 | J18: =J14/J12*365 -> 40 | ... L18: =L14/L12*365 -> 40 | M18: Inventories / revenue x 365 (revenue basis, consistent with forecast)
B19: Payable days | C19: =C15/C12*365 -> 40.685089 | D19: =D15/D12*365 -> 41.605036 | E19: =E15/E12*365 -> 43.638731 | F19: =F15/F12*365 -> 44.820683 | G19: =G15/G12*365 -> 42.214896 | H19: =H15/H12*365 -> 42 | I19: =I15/I12*365 -> 42 | J19: =J15/J12*365 -> 42 | ... L19: =L15/L12*365 -> 42 | M19: Payables / revenue x 365 (revenue basis, consistent with forecast)
B20: Working capital days | C20: =C17+C18-C19 -> 19.464724 | D20: =D17+D18-D19 -> 18.876225 | E20: =E17+E18-E19 -> 21.260224 | F20: =F17+F18-F19 -> 29.438352 | G20: =G17+G18-G19 -> 22.622928 | H20: =H17+H18-H19 -> 22 | I20: =I17+I18-I19 -> 21 | J20: =J17+J18-J19 -> 20 | ... L20: =L17+L18-L19 -> 20 | M20: payable days. 1 day = ~Rs270 Cr (FY27)
B21: (Increase) / decrease in working capital (₹ Cr) | D21: =C16-D16 -> -465.5 | E21: =D16-E16 -> -859.75 | F21: =E16-F16 -> -1995.75 | G21: =F16-G16 -> 640 | H21: =G16-H16 -> -483.4883 | I21: =H16-I16 -> -352.36836 | J21: =I16-J16 -> -300.46579 | K21: =J16-K16 -> -597.99154 | L21: =K16-L16 -> -652.13046 | M21: this year WC. Negative = cash outflow. FY25 (1,996) includes balances acquired with ICL (paid via acquisition, not operations). Feeds cash flow statement
B23: CHECKS
B24: Receivable days difference | H24: =ROUND(H17-H7,0) -> 0 | I24: =ROUND(I17-I7,0) -> 0 | J24: =ROUND(J17-J7,0) -> 0 | K24: =ROUND(K17-K7,0) -> 0 | L24: =ROUND(L17-L7,0) -> 0 | M24: input, 1). Must be 0: balances reflect assumptions
B25: Inventory days difference | H25: =ROUND(H18-H8,0) -> 0 | I25: =ROUND(I18-I8,0) -> 0 | J25: =ROUND(J18-J8,0) -> 0 | K25: =ROUND(K18-K8,0) -> 0 | L25: =ROUND(L18-L8,0) -> 0
B26: Payable days difference | H26: =ROUND(H19-H9,0) -> 0 | I26: =ROUND(I19-I9,0) -> 0 | J26: =ROUND(J19-J9,0) -> 0 | K26: =ROUND(K19-K9,0) -> 0 | L26: =ROUND(L19-L9,0) -> 0

Sheet Debt
B2: DEBT
B3: Model status: | C3: =Check!E4 -> MODEL OK
C5: FY22A | D5: FY23A | E5: FY24A | F5: FY25A | G5: FY26A | H5: FY27E | I5: FY28E | J5: FY29E | K5: FY30E | L5: FY31E | M5: Source/ Reason
B6: INPUT
B7: New borrowings (₹ Cr) | H7: 0 | I7: 0 | J7: 0 | K7: 0 | L7: 0 | M7: 0: no acquisitions assumed; capex funded from operating cash flow
